Workbook

Sheet README
A1: Listing mapping — how to fill this workbook
A3: Example rows on amazon_mapping / flipkart_mapping / myntra_mapping are samples only. Replace them with real column_index + header names from the blank marketplace workbook for your category.
A5: Sheets
A6: pim_contract — customer fields (Mandatory / Optional). Shared by all marketplaces. Add a field on any row through 1000. Every pim_field needs a requirement; status must be OK.
A7: amazon_mapping / flipkart_mapping / myntra_mapping — one sheet per marketplace. Each row is one column from that marketplace’s blank workbook.
A8: lists — dropdown values for fill_mode and generation. Leave alone.
A10: How to fill a marketplace sheet
A11: 1. Put customer fields on pim_contract first (only what you will ask for). Set requirement to Mandatory or Optional on every field.
A12: 2. For each blank-workbook column: set column_index, marketplace_column, and fill_mode. Every row with a column_index needs an explicit fill_mode (use SKIP if you intentionally leave it blank).
A13: 3. status must be OK (green) on every filled pim_contract row and every filled marketplace row before you hand this off.
A14: column_index is the Excel column number from the blank template (unique per marketplace sheet).
A16: Which columns to set for each fill_mode
... A31: Open this file in Microsoft Excel Desktop (File → Open).

Sheet lists
A1: fill_mode | B1: requirement | C1: generation
A2: COPY_PIM | B2: Mandatory | C2: TITLE
A3: COPY_GENERATION | B3: Optional | C3: ITEM_HIGHLIGHTS
A4: ENUM | C4: BULLET_POINTS
A5: AI_TEXT | C5: KEY_FEATURES
A6: CONSTANT | C6: DESCRIPTION
A7: IMAGE | C7: BACKEND_KEYWORDS
A8: SKIP | C8: IMAGE
C9: A_PLUS

Sheet pim_contract
A1: pim_field | B1: requirement | C1: status
A2: SKU | B2: Mandatory | C2: =IF(AND(A2="",B2=""),"",IF(A2="","ERROR: pim_field required",IF(COUNTIF($A$2:$A$1000,A2)>1,"ERROR: duplicate pim_field",IF(B2="","ERROR: requirement required",IF(COUNTIF('lists'!$B$2:$B$3,B2)=0,"ERROR: requirement must be Mandatory or Optional","OK")))))
A3: Brand | B3: Mandatory | C3: =IF(AND(A3="",B3=""),"",IF(A3="","ERROR: pim_field required",IF(COUNTIF($A$2:$A$1000,A3)>1,"ERROR: duplicate pim_field",IF(B3="","ERROR: requirement required",IF(COUNTIF('lists'!$B$2:$B$3,B3)=0,"ERROR: requirement must be Mandatory or Optional","OK")))))
A4: Color | B4: Mandatory | C4: =IF(AND(A4="",B4=""),"",IF(A4="","ERROR: pim_field required",IF(COUNTIF($A$2:$A$1000,A4)>1,"ERROR: duplicate pim_field",IF(B4="","ERROR: requirement required",IF(COUNTIF('lists'!$B$2:$B$3,B4)=0,"ERROR: requirement must be Mandatory or Optional","OK")))))
A5: Size | B5: Optional | C5: =IF(AND(A5="",B5=""),"",IF(A5="","ERROR: pim_field required",IF(COUNTIF($A$2:$A$1000,A5)>1,"ERROR: duplicate pim_field",IF(B5="","ERROR: requirement required",IF(COUNTIF('lists'!$B$2:$B$3,B5)=0,"ERROR: requirement must be Mandatory or Optional","OK")))))
C6: =IF(AND(A6="",B6=""),"",IF(A6="","ERROR: pim_field required",IF(COUNTIF($A$2:$A$1000,A6)>1,"ERROR: duplicate pim_field",IF(B6="","ERROR: requirement required",IF(COUNTIF('lists'!$B$2:$B$3,B6)=0,"ERROR: requirement must be Mandatory or Optional","OK")))))
C7: =IF(AND(A7="",B7=""),"",IF(A7="","ERROR: pim_field required",IF(COUNTIF($A$2:$A$1000,A7)>1,"ERROR: duplicate pim_field",IF(B7="","ERROR: requirement required",IF(COUNTIF('lists'!$B$2:$B$3,B7)=0,"ERROR: requirement must be Mandatory or Optional","OK")))))
C8: =IF(AND(A8="",B8=""),"",IF(A8="","ERROR: pim_field required",IF(COUNTIF($A$2:$A$1000,A8)>1,"ERROR: duplicate pim_field",IF(B8="","ERROR: requirement required",IF(COUNTIF('lists'!$B$2:$B$3,B8)=0,"ERROR: requirement must be Mandatory or Optional","OK")))))
C9: =IF(AND(A9="",B9=""),"",IF(A9="","ERROR: pim_field required",IF(COUNTIF($A$2:$A$1000,A9)>1,"ERROR: duplicate pim_field",IF(B9="","ERROR: requirement required",IF(COUNTIF('lists'!$B$2:$B$3,B9)=0,"ERROR: requirement must be Mandatory or Optional","OK")))))
C10: =IF(AND(A10="",B10=""),"",IF(A10="","ERROR: pim_field required",IF(COUNTIF($A$2:$A$1000,A10)>1,"ERROR: duplicate pim_field",IF(B10="","ERROR: requirement required",IF(COUNTIF('lists'!$B$2:$B$3,B10)=0,"ERROR: requirement must be Mandatory or Optional","OK")))))
C11: =IF(AND(A11="",B11=""),"",IF(A11="","ERROR: pim_field required",IF(COUNTIF($A$2:$A$1000,A11)>1,"ERROR: duplicate pim_field",IF(B11="","ERROR: requirement required",IF(COUNTIF('lists'!$B$2:$B$3,B11)=0,"ERROR: requirement must be Mandatory or Optional","OK")))))
C12: =IF(AND(A12="",B12=""),"",IF(A12="","ERROR: pim_field required",IF(COUNTIF($A$2:$A$1000,A12)>1,"ERROR: duplicate pim_field",IF(B12="","ERROR: requirement required",IF(COUNTIF('lists'!$B$2:$B$3,B12)=0,"ERROR: requirement must be Mandatory or Optional","OK")))))
C13: =IF(AND(A13="",B13=""),"",IF(A13="","ERROR: pim_field required",IF(COUNTIF($A$2:$A$1000,A13)>1,"ERROR: duplicate pim_field",IF(B13="","ERROR: requirement required",IF(COUNTIF('lists'!$B$2:$B$3,B13)=0,"ERROR: requirement must be Mandatory or Optional","OK")))))
C14: =IF(AND(A14="",B14=""),"",IF(A14="","ERROR: pim_field required",IF(COUNTIF($A$2:$A$1000,A14)>1,"ERROR: duplicate pim_field",IF(B14="","ERROR: requirement required",IF(COUNTIF('lists'!$B$2:$B$3,B14)=0,"ERROR: requirement must be Mandatory or Optional","OK")))))
C15: =IF(AND(A15="",B15=""),"",IF(A15="","ERROR: pim_field required",IF(COUNTIF($A$2:$A$1000,A15)>1,"ERROR: duplicate pim_field",IF(B15="","ERROR: requirement required",IF(COUNTIF('lists'!$B$2:$B$3,B15)=0,"ERROR: requirement must be Mandatory or Optional","OK")))))
C16: =IF(AND(A16="",B16=""),"",IF(A16="","ERROR: pim_field required",IF(COUNTIF($A$2:$A$1000,A16)>1,"ERROR: duplicate pim_field",IF(B16="","ERROR: requirement required",IF(COUNTIF('lists'!$B$2:$B$3,B16)=0,"ERROR: requirement must be Mandatory or Optional","OK")))))
C17: =IF(AND(A17="",B17=""),"",IF(A17="","ERROR: pim_field required",IF(COUNTIF($A$2:$A$1000,A17)>1,"ERROR: duplicate pim_field",IF(B17="","ERROR: requirement required",IF(COUNTIF('lists'!$B$2:$B$3,B17)=0,"ERROR: requirement must be Mandatory or Optional","OK")))))
... C1000: =IF(AND(A1000="",B1000=""),"",IF(A1000="","ERROR: pim_field required",IF(COUNTIF($A$2:$A$1000,A1000)>1,"ERROR: duplicate pim_field",IF(B1000="","ERROR: requirement required",IF(COUNTIF('lists'!$B$2:$B$3,B1000)=0,"ERROR: requirement must be Mandatory or Optional","OK")))))

Sheet amazon_mapping
A1: column_index | B1: marketplace_column | C1: fill_mode | D1: pim_field | E1: generation | F1: constant_value | G1: status
A2: 1 | B2: SKU | C2: COPY_PIM | D2: SKU | G2: =IF(AND(OR(A2="",A2=0),C2=""),"",IF(OR(A2="",A2=0),"ERROR: column_index required",IF(B2="","ERROR: marketplace_column required",IF(COUNTIF($A$2:$A$320,A2)>1,"ERROR: duplicate column_index",IF(C2="","ERROR: fill_mode required",IF(COUNTIF('lists'!$A$2:$A$8,C2)=0,"ERROR: invalid fill_mode",IF(C2="COPY_PIM",IF(D2="","ERROR: COPY_PIM requires pim_field",IF(NOT(COUNTIF('pim_contract'!$A$2:$A$1000,D2)>0),"ERROR: pim_field is not on pim_contract",IF(NOT((COUNTIFS('pim_contract'!$A$2:$A$1000,D2,'pim_contract'!$B$2:$B$1000,"Mandatory")+COUNTIFS('pim_contract'!$A$2:$A$1000,D2,'pim_contract'!$B$2:$B$1000,"Optional"))>0),"ERROR: pim_contract requirement required for this pim_field",IF(E2<>"","ERROR: generation must be blank for COPY_PIM",IF(F2<>"","ERROR: constant_value must be blank for COPY_PIM","OK"))))),IF(C2="ENUM",IF(E2<>"","ERROR: generation must be blank for ENUM",IF(F2<>"","ERROR: constant_value must be blank for ENUM",IF(D2="","OK",IF(NOT(COUNTIF('pim_contract'!$A$2:$A$1000,D2)>0),"ERROR: pim_field is not on pim_contract",IF(NOT((COUNTIFS('pim_contract'!$A$2:$A$1000,D2,'pim_contract'!$B$2:$B$1000,"Mandatory")+COUNTIFS('pim_contract'!$A$2:$A$1000,D2,'pim_contract'!$B$2:$B$1000,"Optional"))>0),"ERROR: pim_contract requirement required for this pim_field","OK"))))),IF(C2="AI_TEXT",IF(E2<>"","ERROR: generation must be blank for AI_TEXT",IF(F2<>"","ERROR: constant_value must be blank for AI_TEXT",IF(D2="","OK",IF(NOT(COUNTIF('pim_contract'!$A$2:$A$1000,D2)>0),"ERROR: pim_field is not on pim_contract",IF(NOT((COUNTIFS('pim_contract'!$A$2:$A$1000,D2,'pim_contract'!$B$2:$B$1000,"Mandatory")+COUNTIFS('pim_contract'!$A$2:$A$1000,D2,'pim_contract'!$B$2:$B$1000,"Optional"))>0),"ERROR: pim_contract requirement required for this pim_field","OK"))))),IF(C2="COPY_GENERATION",IF(E2="","ERROR: COPY_GENERATION requires generation",IF(COUNTIF('lists'!$C$2:$C$9,E2)=0,"ERROR: generation is not in the lists sheet",IF(D2<>"","ERROR: pim_field must be blank for COPY_GENERATION",IF(F2<>"","ERROR: constant_value must be blank for COPY_GENERATION","OK")))),IF(C2="IMAGE",IF(E2="","ERROR: IMAGE requires generation",IF(COUNTIF('lists'!$C$2:$C$9,E2)=0,"ERROR: generation is not in the lists sheet",IF(D2<>"","ERROR: pim_field must be blank for IMAGE",IF(F2<>"","ERROR: constant_value must be blank for IMAGE","OK")))),IF(C2="CONSTANT",IF(F2="","ERROR: CONSTANT requires constant_value",IF(D2<>"","ERROR: pim_field must be blank for CONSTANT",IF(E2<>"","ERROR: generation must be blank for CONSTANT","OK"))),IF(C2="SKIP",IF(D2<>"","ERROR: pim_field must be blank for SKIP",IF(E2<>"","ERROR: generation must be blank for SKIP",IF(F2<>"","ERROR: constant_value must be blank for SKIP","OK"))),"ERROR: unhandled fill_mode")))))))))))))
A3: 2 | B3: Product Type | C3: CONSTANT | F3: EXAMPLE | G3: =IF(AND(OR(A3="",A3=0),C3=""),"",IF(OR(A3="",A3=0),"ERROR: column_index required",IF(B3="","ERROR: marketplace_column required",IF(COUNTIF($A$2:$A$320,A3)>1,"ERROR: duplicate column_index",IF(C3="","ERROR: fill_mode required",IF(COUNTIF('lists'!$A$2:$A$8,C3)=0,"ERROR: invalid fill_mode",IF(C3="COPY_PIM",IF(D3="","ERROR: COPY_PIM requires pim_field",IF(NOT(COUNTIF('pim_contract'!$A$2:$A$1000,D3)>0),"ERROR: pim_field is not on pim_contract",IF(NOT((COUNTIFS('pim_contract'!$A$2:$A$1000,D3,'pim_contract'!$B$2:$B$1000,"Mandatory")+COUNTIFS('pim_contract'!$A$2:$A$1000,D3,'pim_contract'!$B$2:$B$1000,"Optional"))>0),"ERROR: pim_contract requirement required for this pim_field",IF(E3<>"","ERROR: generation must be blank for COPY_PIM",IF(F3<>"","ERROR: constant_value must be blank for COPY_PIM","OK"))))),IF(C3="ENUM",IF(E3<>"","ERROR: generation must be blank for ENUM",IF(F3<>"","ERROR: constant_value must be blank for ENUM",IF(D3="","OK",IF(NOT(COUNTIF('pim_contract'!$A$2:$A$1000,D3)>0),"ERROR: pim_field is not on pim_contract",IF(NOT((COUNTIFS('pim_contract'!$A$2:$A$1000,D3,'pim_contract'!$B$2:$B$1000,"Mandatory")+COUNTIFS('pim_contract'!$A$2:$A$1000,D3,'pim_contract'!$B$2:$B$1000,"Optional"))>0),"ERROR: pim_contract requirement required for this pim_field","OK"))))),IF(C3="AI_TEXT",IF(E3<>"","ERROR: generation must be blank for AI_TEXT",IF(F3<>"","ERROR: constant_value must be blank for AI_TEXT",IF(D3="","OK",IF(NOT(COUNTIF('pim_contract'!$A$2:$A$1000,D3)>0),"ERROR: pim_field is not on pim_contract",IF(NOT((COUNTIFS('pim_contract'!$A$2:$A$1000,D3,'pim_contract'!$B$2:$B$1000,"Mandatory")+COUNTIFS('pim_contract'!$A$2:$A$1000,D3,'pim_contract'!$B$2:$B$1000,"Optional"))>0),"ERROR: pim_contract requirement required for this pim_field","OK"))))),IF(C3="COPY_GENERATION",IF(E3="","ERROR: COPY_GENERATION requires generation",IF(COUNTIF('lists'!$C$2:$C$9,E3)=0,"ERROR: generation is not in the lists sheet",IF(D3<>"","ERROR: pim_field must be blank for COPY_GENERATION",IF(F3<>"","ERROR: constant_value must be blank for COPY_GENERATION","OK")))),IF(C3="IMAGE",IF(E3="","ERROR: IMAGE requires generation",IF(COUNTIF('lists'!$C$2:$C$9,E3)=0,"ERROR: generation is not in the lists sheet",IF(D3<>"","ERROR: pim_field must be blank for IMAGE",IF(F3<>"","ERROR: constant_value must be blank for IMAGE","OK")))),IF(C3="CONSTANT",IF(F3="","ERROR: CONSTANT requires constant_value",IF(D3<>"","ERROR: pim_field must be blank for CONSTANT",IF(E3<>"","ERROR: generation must be blank for CONSTANT","OK"))),IF(C3="SKIP",IF(D3<>"","ERROR: pim_field must be blank for SKIP",IF(E3<>"","ERROR: generation must be blank for SKIP",IF(F3<>"","ERROR: constant_value must be blank for SKIP","OK"))),"ERROR: unhandled fill_mode")))))))))))))
A4: 3 | B4: Parentage Level | C4: ENUM | G4: =IF(AND(OR(A4="",A4=0),C4=""),"",IF(OR(A4="",A4=0),"ERROR: column_index required",IF(B4="","ERROR: marketplace_column required",IF(COUNTIF($A$2:$A$320,A4)>1,"ERROR: duplicate column_index",IF(C4="","ERROR: fill_mode required",IF(COUNTIF('lists'!$A$2:$A$8,C4)=0,"ERROR: invalid fill_mode",IF(C4="COPY_PIM",IF(D4="","ERROR: COPY_PIM requires pim_field",IF(NOT(COUNTIF('pim_contract'!$A$2:$A$1000,D4)>0),"ERROR: pim_field is not on pim_contract",IF(NOT((COUNTIFS('pim_contract'!$A$2:$A$1000,D4,'pim_contract'!$B$2:$B$1000,"Mandatory")+COUNTIFS('pim_contract'!$A$2:$A$1000,D4,'pim_contract'!$B$2:$B$1000,"Optional"))>0),"ERROR: pim_contract requirement required for this pim_field",IF(E4<>"","ERROR: generation must be blank for COPY_PIM",IF(F4<>"","ERROR: constant_value must be blank for COPY_PIM","OK"))))),IF(C4="ENUM",IF(E4<>"","ERROR: generation must be blank for ENUM",IF(F4<>"","ERROR: constant_value must be blank for ENUM",IF(D4="","OK",IF(NOT(COUNTIF('pim_contract'!$A$2:$A$1000,D4)>0),"ERROR: pim_field is not on pim_contract",IF(NOT((COUNTIFS('pim_contract'!$A$2:$A$1000,D4,'pim_contract'!$B$2:$B$1000,"Mandatory")+COUNTIFS('pim_contract'!$A$2:$A$1000,D4,'pim_contract'!$B$2:$B$1000,"Optional"))>0),"ERROR: pim_contract requirement required for this pim_field","OK"))))),IF(C4="AI_TEXT",IF(E4<>"","ERROR: generation must be blank for AI_TEXT",IF(F4<>"","ERROR: constant_value must be blank for AI_TEXT",IF(D4="","OK",IF(NOT(COUNTIF('pim_contract'!$A$2:$A$1000,D4)>0),"ERROR: pim_field is not on pim_contract",IF(NOT((COUNTIFS('pim_contract'!$A$2:$A$1000,D4,'pim_contract'!$B$2:$B$1000,"Mandatory")+COUNTIFS('pim_contract'!$A$2:$A$1000,D4,'pim_contract'!$B$2:$B$1000,"Optional"))>0),"ERROR: pim_contract requirement required for this pim_field","OK"))))),IF(C4="COPY_GENERATION",IF(E4="","ERROR: COPY_GENERATION requires generation",IF(COUNTIF('lists'!$C$2:$C$9,E4)=0,"ERROR: generation is not in the lists sheet",IF(D4<>"","ERROR: pim_field must be blank for COPY_GENERATION",IF(F4<>"","ERROR: constant_value must be blank for COPY_GENERATION","OK")))),IF(C4="IMAGE",IF(E4="","ERROR: IMAGE requires generation",IF(COUNTIF('lists'!$C$2:$C$9,E4)=0,"ERROR: generation is not in the lists sheet",IF(D4<>"","ERROR: pim_field must be blank for IMAGE",IF(F4<>"","ERROR: constant_value must be blank for IMAGE","OK")))),IF(C4="CONSTANT",IF(F4="","ERROR: CONSTANT requires constant_value",IF(D4<>"","ERROR: pim_field must be blank for CONSTANT",IF(E4<>"","ERROR: generation must be blank for CONSTANT","OK"))),IF(C4="SKIP",IF(D4<>"","ERROR: pim_field must be blank for SKIP",IF(E4<>"","ERROR: generation must be blank for SKIP",IF(F4<>"","ERROR: constant_value must be blank for SKIP","OK"))),"ERROR: unhandled fill_mode")))))))))))))
A5: 4 | B5: Brand Name | C5: ENUM | D5: Brand | G5: =IF(AND(OR(A5="",A5=0),C5=""),"",IF(OR(A5="",A5=0),"ERROR: column_index required",IF(B5="","ERROR: marketplace_column required",IF(COUNTIF($A$2:$A$320,A5)>1,"ERROR: duplicate column_index",IF(C5="","ERROR: fill_mode required",IF(COUNTIF('lists'!$A$2:$A$8,C5)=0,"ERROR: invalid fill_mode",IF(C5="COPY_PIM",IF(D5="","ERROR: COPY_PIM requires pim_field",IF(NOT(COUNTIF('pim_contract'!$A$2:$A$1000,D5)>0),"ERROR: pim_field is not on pim_contract",IF(NOT((COUNTIFS('pim_contract'!$A$2:$A$1000,D5,'pim_contract'!$B$2:$B$1000,"Mandatory")+COUNTIFS('pim_contract'!$A$2:$A$1000,D5,'pim_contract'!$B$2:$B$1000,"Optional"))>0),"ERROR: pim_contract requirement required for this pim_field",IF(E5<>"","ERROR: generation must be blank for COPY_PIM",IF(F5<>"","ERROR: constant_value must be blank for COPY_PIM","OK"))))),IF(C5="ENUM",IF(E5<>"","ERROR: generation must be blank for ENUM",IF(F5<>"","ERROR: constant_value must be blank for ENUM",IF(D5="","OK",IF(NOT(COUNTIF('pim_contract'!$A$2:$A$1000,D5)>0),"ERROR: pim_field is not on pim_contract",IF(NOT((COUNTIFS('pim_contract'!$A$2:$A$1000,D5,'pim_contract'!$B$2:$B$1000,"Mandatory")+COUNTIFS('pim_contract'!$A$2:$A$1000,D5,'pim_contract'!$B$2:$B$1000,"Optional"))>0),"ERROR: pim_contract requirement required for this pim_field","OK"))))),IF(C5="AI_TEXT",IF(E5<>"","ERROR: generation must be blank for AI_TEXT",IF(F5<>"","ERROR: constant_value must be blank for AI_TEXT",IF(D5="","OK",IF(NOT(COUNTIF('pim_contract'!$A$2:$A$1000,D5)>0),"ERROR: pim_field is not on pim_contract",IF(NOT((COUNTIFS('pim_contract'!$A$2:$A$1000,D5,'pim_contract'!$B$2:$B$1000,"Mandatory")+COUNTIFS('pim_contract'!$A$2:$A$1000,D5,'pim_contract'!$B$2:$B$1000,"Optional"))>0),"ERROR: pim_contract requirement required for this pim_field","OK"))))),IF(C5="COPY_GENERATION",IF(E5="","ERROR: COPY_GENERATION requires generation",IF(COUNTIF('lists'!$C$2:$C$9,E5)=0,"ERROR: generation is not in the lists sheet",IF(D5<>"","ERROR: pim_field must be blank for COPY_GENERATION",IF(F5<>"","ERROR: constant_value must be blank for COPY_GENERATION","OK")))),IF(C5="IMAGE",IF(E5="","ERROR: IMAGE requires generation",IF(COUNTIF('lists'!$C$2:$C$9,E5)=0,"ERROR: generation is not in the lists sheet",IF(D5<>"","ERROR: pim_field must be blank for IMAGE",IF(F5<>"","ERROR: constant_value must be blank for IMAGE","OK")))),IF(C5="CONSTANT",IF(F5="","ERROR: CONSTANT requires constant_value",IF(D5<>"","ERROR: pim_field must be blank for CONSTANT",IF(E5<>"","ERROR: generation must be blank for CONSTANT","OK"))),IF(C5="SKIP",IF(D5<>"","ERROR: pim_field must be blank for SKIP",IF(E5<>"","ERROR: generation must be blank for SKIP",IF(F5<>"","ERROR: constant_value must be blank for SKIP","OK"))),"ERROR: unhandled fill_mode")))))))))))))
A6: 5 | B6: Unused column | C6: SKIP | G6: =IF(AND(OR(A6="",A6=0),C6=""),"",IF(OR(A6="",A6=0),"ERROR: column_index required",IF(B6="","ERROR: marketplace_column required",IF(COUNTIF($A$2:$A$320,A6)>1,"ERROR: duplicate column_index",IF(C6="","ERROR: fill_mode required",IF(COUNTIF('lists'!$A$2:$A$8,C6)=0,"ERROR: invalid fill_mode",IF(C6="COPY_PIM",IF(D6="","ERROR: COPY_PIM requires pim_field",IF(NOT(COUNTIF('pim_contract'!$A$2:$A$1000,D6)>0),"ERROR: pim_field is not on pim_contract",IF(NOT((COUNTIFS('pim_contract'!$A$2:$A$1000,D6,'pim_contract'!$B$2:$B$1000,"Mandatory")+COUNTIFS('pim_contract'!$A$2:$A$1000,D6,'pim_contract'!$B$2:$B$1000,"Optional"))>0),"ERROR: pim_contract requirement required for this pim_field",IF(E6<>"","ERROR: generation must be blank for COPY_PIM",IF(F6<>"","ERROR: constant_value must be blank for COPY_PIM","OK"))))),IF(C6="ENUM",IF(E6<>"","ERROR: generation must be blank for ENUM",IF(F6<>"","ERROR: constant_value must be blank for ENUM",IF(D6="","OK",IF(NOT(COUNTIF('pim_contract'!$A$2:$A$1000,D6)>0),"ERROR: pim_field is not on pim_contract",IF(NOT((COUNTIFS('pim_contract'!$A$2:$A$1000,D6,'pim_contract'!$B$2:$B$1000,"Mandatory")+COUNTIFS('pim_contract'!$A$2:$A$1000,D6,'pim_contract'!$B$2:$B$1000,"Optional"))>0),"ERROR: pim_contract requirement required for this pim_field","OK"))))),IF(C6="AI_TEXT",IF(E6<>"","ERROR: generation must be blank for AI_TEXT",IF(F6<>"","ERROR: constant_value must be blank for AI_TEXT",IF(D6="","OK",IF(NOT(COUNTIF('pim_contract'!$A$2:$A$1000,D6)>0),"ERROR: pim_field is not on pim_contract",IF(NOT((COUNTIFS('pim_contract'!$A$2:$A$1000,D6,'pim_contract'!$B$2:$B$1000,"Mandatory")+COUNTIFS('pim_contract'!$A$2:$A$1000,D6,'pim_contract'!$B$2:$B$1000,"Optional"))>0),"ERROR: pim_contract requirement required for this pim_field","OK"))))),IF(C6="COPY_GENERATION",IF(E6="","ERROR: COPY_GENERATION requires generation",IF(COUNTIF('lists'!$C$2:$C$9,E6)=0,"ERROR: generation is not in the lists sheet",IF(D6<>"","ERROR: pim_field must be blank for COPY_GENERATION",IF(F6<>"","ERROR: constant_value must be blank for COPY_GENERATION","OK")))),IF(C6="IMAGE",IF(E6="","ERROR: IMAGE requires generation",IF(COUNTIF('lists'!$C$2:$C$9,E6)=0,"ERROR: generation is not in the lists sheet",IF(D6<>"","ERROR: pim_field must be blank for IMAGE",IF(F6<>"","ERROR: constant_value must be blank for IMAGE","OK")))),IF(C6="CONSTANT",IF(F6="","ERROR: CONSTANT requires constant_value",IF(D6<>"","ERROR: pim_field must be blank for CONSTANT",IF(E6<>"","ERROR: generation must be blank for CONSTANT","OK"))),IF(C6="SKIP",IF(D6<>"","ERROR: pim_field must be blank for SKIP",IF(E6<>"","ERROR: generation must be blank for SKIP",IF(F6<>"","ERROR: constant_value must be blank for SKIP","OK"))),"ERROR: unhandled fill_mode")))))))))))))
A7: 6 | B7: Item Name | C7: COPY_GENERATION | E7: TITLE | G7: =IF(AND(OR(A7="",A7=0),C7=""),"",IF(OR(A7="",A7=0),"ERROR: column_index required",IF(B7="","ERROR: marketplace_column required",IF(COUNTIF($A$2:$A$320,A7)>1,"ERROR: duplicate column_index",IF(C7="","ERROR: fill_mode required",IF(COUNTIF('lists'!$A$2:$A$8,C7)=0,"ERROR: invalid fill_mode",IF(C7="COPY_PIM",IF(D7="","ERROR: COPY_PIM requires pim_field",IF(NOT(COUNTIF('pim_contract'!$A$2:$A$1000,D7)>0),"ERROR: pim_field is not on pim_contract",IF(NOT((COUNTIFS('pim_contract'!$A$2:$A$1000,D7,'pim_contract'!$B$2:$B$1000,"Mandatory")+COUNTIFS('pim_contract'!$A$2:$A$1000,D7,'pim_contract'!$B$2:$B$1000,"Optional"))>0),"ERROR: pim_contract requirement required for this pim_field",IF(E7<>"","ERROR: generation must be blank for COPY_PIM",IF(F7<>"","ERROR: constant_value must be blank for COPY_PIM","OK"))))),IF(C7="ENUM",IF(E7<>"","ERROR: generation must be blank for ENUM",IF(F7<>"","ERROR: constant_value must be blank for ENUM",IF(D7="","OK",IF(NOT(COUNTIF('pim_contract'!$A$2:$A$1000,D7)>0),"ERROR: pim_field is not on pim_contract",IF(NOT((COUNTIFS('pim_contract'!$A$2:$A$1000,D7,'pim_contract'!$B$2:$B$1000,"Mandatory")+COUNTIFS('pim_contract'!$A$2:$A$1000,D7,'pim_contract'!$B$2:$B$1000,"Optional"))>0),"ERROR: pim_contract requirement required for this pim_field","OK"))))),IF(C7="AI_TEXT",IF(E7<>"","ERROR: generation must be blank for AI_TEXT",IF(F7<>"","ERROR: constant_value must be blank for AI_TEXT",IF(D7="","OK",IF(NOT(COUNTIF('pim_contract'!$A$2:$A$1000,D7)>0),"ERROR: pim_field is not on pim_contract",IF(NOT((COUNTIFS('pim_contract'!$A$2:$A$1000,D7,'pim_contract'!$B$2:$B$1000,"Mandatory")+COUNTIFS('pim_contract'!$A$2:$A$1000,D7,'pim_contract'!$B$2:$B$1000,"Optional"))>0),"ERROR: pim_contract requirement required for this pim_field","OK"))))),IF(C7="COPY_GENERATION",IF(E7="","ERROR: COPY_GENERATION requires generation",IF(COUNTIF('lists'!$C$2:$C$9,E7)=0,"ERROR: generation is not in the lists sheet",IF(D7<>"","ERROR: pim_field must be blank for COPY_GENERATION",IF(F7<>"","ERROR: constant_value must be blank for COPY_GENERATION","OK")))),IF(C7="IMAGE",IF(E7="","ERROR: IMAGE requires generation",IF(COUNTIF('lists'!$C$2:$C$9,E7)=0,"ERROR: generation is not in the lists sheet",IF(D7<>"","ERROR: pim_field must be blank for IMAGE",IF(F7<>"","ERROR: constant_value must be blank for IMAGE","OK")))),IF(C7="CONSTANT",IF(F7="","ERROR: CONSTANT requires constant_value",IF(D7<>"","ERROR: pim_field must be blank for CONSTANT",IF(E7<>"","ERROR: generation must be blank for CONSTANT","OK"))),IF(C7="SKIP",IF(D7<>"","ERROR: pim_field must be blank for SKIP",IF(E7<>"","ERROR: generation must be blank for SKIP",IF(F7<>"","ERROR: constant_value must be blank for SKIP","OK"))),"ERROR: unhandled fill_mode")))))))))))))
A8: 7 | B8: Item Highlight | C8: COPY_GENERATION | E8: ITEM_HIGHLIGHTS | G8: =IF(AND(OR(A8="",A8=0),C8=""),"",IF(OR(A8="",A8=0),"ERROR: column_index required",IF(B8="","ERROR: marketplace_column required",IF(COUNTIF($A$2:$A$320,A8)>1,"ERROR: duplicate column_index",IF(C8="","ERROR: fill_mode required",IF(COUNTIF('lists'!$A$2:$A$8,C8)=0,"ERROR: invalid fill_mode",IF(C8="COPY_PIM",IF(D8="","ERROR: COPY_PIM requires pim_field",IF(NOT(COUNTIF('pim_contract'!$A$2:$A$1000,D8)>0),"ERROR: pim_field is not on pim_contract",IF(NOT((COUNTIFS('pim_contract'!$A$2:$A$1000,D8,'pim_contract'!$B$2:$B$1000,"Mandatory")+COUNTIFS('pim_contract'!$A$2:$A$1000,D8,'pim_contract'!$B$2:$B$1000,"Optional"))>0),"ERROR: pim_contract requirement required for this pim_field",IF(E8<>"","ERROR: generation must be blank for COPY_PIM",IF(F8<>"","ERROR: constant_value must be blank for COPY_PIM","OK"))))),IF(C8="ENUM",IF(E8<>"","ERROR: generation must be blank for ENUM",IF(F8<>"","ERROR: constant_value must be blank for ENUM",IF(D8="","OK",IF(NOT(COUNTIF('pim_contract'!$A$2:$A$1000,D8)>0),"ERROR: pim_field is not on pim_contract",IF(NOT((COUNTIFS('pim_contract'!$A$2:$A$1000,D8,'pim_contract'!$B$2:$B$1000,"Mandatory")+COUNTIFS('pim_contract'!$A$2:$A$1000,D8,'pim_contract'!$B$2:$B$1000,"Optional"))>0),"ERROR: pim_contract requirement required for this pim_field","OK"))))),IF(C8="AI_TEXT",IF(E8<>"","ERROR: generation must be blank for AI_TEXT",IF(F8<>"","ERROR: constant_value must be blank for AI_TEXT",IF(D8="","OK",IF(NOT(COUNTIF('pim_contract'!$A$2:$A$1000,D8)>0),"ERROR: pim_field is not on pim_contract",IF(NOT((COUNTIFS('pim_contract'!$A$2:$A$1000,D8,'pim_contract'!$B$2:$B$1000,"Mandatory")+COUNTIFS('pim_contract'!$A$2:$A$1000,D8,'pim_contract'!$B$2:$B$1000,"Optional"))>0),"ERROR: pim_contract requirement required for this pim_field","OK"))))),IF(C8="COPY_GENERATION",IF(E8="","ERROR: COPY_GENERATION requires generation",IF(COUNTIF('lists'!$C$2:$C$9,E8)=0,"ERROR: generation is not in the lists sheet",IF(D8<>"","ERROR: pim_field must be blank for COPY_GENERATION",IF(F8<>"","ERROR: constant_value must be blank for COPY_GENERATION","OK")))),IF(C8="IMAGE",IF(E8="","ERROR: IMAGE requires generation",IF(COUNTIF('lists'!$C$2:$C$9,E8)=0,"ERROR: generation is not in the lists sheet",IF(D8<>"","ERROR: pim_field must be blank for IMAGE",IF(F8<>"","ERROR: constant_value must be blank for IMAGE","OK")))),IF(C8="CONSTANT",IF(F8="","ERROR: CONSTANT requires constant_value",IF(D8<>"","ERROR: pim_field must be blank for CONSTANT",IF(E8<>"","ERROR: generation must be blank for CONSTANT","OK"))),IF(C8="SKIP",IF(D8<>"","ERROR: pim_field must be blank for SKIP",IF(E8<>"","ERROR: generation must be blank for SKIP",IF(F8<>"","ERROR: constant_value must be blank for SKIP","OK"))),"ERROR: unhandled fill_mode")))))))))))))
A9: 8 | B9: Item Highlight | C9: COPY_GENERATION | E9: ITEM_HIGHLIGHTS | G9: =IF(AND(OR(A9="",A9=0),C9=""),"",IF(OR(A9="",A9=0),"ERROR: column_index required",IF(B9="","ERROR: marketplace_column required",IF(COUNTIF($A$2:$A$320,A9)>1,"ERROR: duplicate column_index",IF(C9="","ERROR: fill_mode required",IF(COUNTIF('lists'!$A$2:$A$8,C9)=0,"ERROR: invalid fill_mode",IF(C9="COPY_PIM",IF(D9="","ERROR: COPY_PIM requires pim_field",IF(NOT(COUNTIF('pim_contract'!$A$2:$A$1000,D9)>0),"ERROR: pim_field is not on pim_contract",IF(NOT((COUNTIFS('pim_contract'!$A$2:$A$1000,D9,'pim_contract'!$B$2:$B$1000,"Mandatory")+COUNTIFS('pim_contract'!$A$2:$A$1000,D9,'pim_contract'!$B$2:$B$1000,"Optional"))>0),"ERROR: pim_contract requirement required for this pim_field",IF(E9<>"","ERROR: generation must be blank for COPY_PIM",IF(F9<>"","ERROR: constant_value must be blank for COPY_PIM","OK"))))),IF(C9="ENUM",IF(E9<>"","ERROR: generation must be blank for ENUM",IF(F9<>"","ERROR: constant_value must be blank for ENUM",IF(D9="","OK",IF(NOT(COUNTIF('pim_contract'!$A$2:$A$1000,D9)>0),"ERROR: pim_field is not on pim_contract",IF(NOT((COUNTIFS('pim_contract'!$A$2:$A$1000,D9,'pim_contract'!$B$2:$B$1000,"Mandatory")+COUNTIFS('pim_contract'!$A$2:$A$1000,D9,'pim_contract'!$B$2:$B$1000,"Optional"))>0),"ERROR: pim_contract requirement required for this pim_field","OK"))))),IF(C9="AI_TEXT",IF(E9<>"","ERROR: generation must be blank for AI_TEXT",IF(F9<>"","ERROR: constant_value must be blank for AI_TEXT",IF(D9="","OK",IF(NOT(COUNTIF('pim_contract'!$A$2:$A$1000,D9)>0),"ERROR: pim_field is not on pim_contract",IF(NOT((COUNTIFS('pim_contract'!$A$2:$A$1000,D9,'pim_contract'!$B$2:$B$1000,"Mandatory")+COUNTIFS('pim_contract'!$A$2:$A$1000,D9,'pim_contract'!$B$2:$B$1000,"Optional"))>0),"ERROR: pim_contract requirement required for this pim_field","OK"))))),IF(C9="COPY_GENERATION",IF(E9="","ERROR: COPY_GENERATION requires generation",IF(COUNTIF('lists'!$C$2:$C$9,E9)=0,"ERROR: generation is not in the lists sheet",IF(D9<>"","ERROR: pim_field must be blank for COPY_GENERATION",IF(F9<>"","ERROR: constant_value must be blank for COPY_GENERATION","OK")))),IF(C9="IMAGE",IF(E9="","ERROR: IMAGE requires generation",IF(COUNTIF('lists'!$C$2:$C$9,E9)=0,"ERROR: generation is not in the lists sheet",IF(D9<>"","ERROR: pim_field must be blank for IMAGE",IF(F9<>"","ERROR: constant_value must be blank for IMAGE","OK")))),IF(C9="CONSTANT",IF(F9="","ERROR: CONSTANT requires constant_value",IF(D9<>"","ERROR: pim_field must be blank for CONSTANT",IF(E9<>"","ERROR: generation must be blank for CONSTANT","OK"))),IF(C9="SKIP",IF(D9<>"","ERROR: pim_field must be blank for SKIP",IF(E9<>"","ERROR: generation must be blank for SKIP",IF(F9<>"","ERROR: constant_value must be blank for SKIP","OK"))),"ERROR: unhandled fill_mode")))))))))))))
A10: 9 | B10: Main Image URL | C10: IMAGE | E10: IMAGE | G10: =IF(AND(OR(A10="",A10=0),C10=""),"",IF(OR(A10="",A10=0),"ERROR: column_index required",IF(B10="","ERROR: marketplace_column required",IF(COUNTIF($A$2:$A$320,A10)>1,"ERROR: duplicate column_index",IF(C10="","ERROR: fill_mode required",IF(COUNTIF('lists'!$A$2:$A$8,C10)=0,"ERROR: invalid fill_mode",IF(C10="COPY_PIM",IF(D10="","ERROR: COPY_PIM requires pim_field",IF(NOT(COUNTIF('pim_contract'!$A$2:$A$1000,D10)>0),"ERROR: pim_field is not on pim_contract",IF(NOT((COUNTIFS('pim_contract'!$A$2:$A$1000,D10,'pim_contract'!$B$2:$B$1000,"Mandatory")+COUNTIFS('pim_contract'!$A$2:$A$1000,D10,'pim_contract'!$B$2:$B$1000,"Optional"))>0),"ERROR: pim_contract requirement required for this pim_field",IF(E10<>"","ERROR: generation must be blank for COPY_PIM",IF(F10<>"","ERROR: constant_value must be blank for COPY_PIM","OK"))))),IF(C10="ENUM",IF(E10<>"","ERROR: generation must be blank for ENUM",IF(F10<>"","ERROR: constant_value must be blank for ENUM",IF(D10="","OK",IF(NOT(COUNTIF('pim_contract'!$A$2:$A$1000,D10)>0),"ERROR: pim_field is not on pim_contract",IF(NOT((COUNTIFS('pim_contract'!$A$2:$A$1000,D10,'pim_contract'!$B$2:$B$1000,"Mandatory")+COUNTIFS('pim_contract'!$A$2:$A$1000,D10,'pim_contract'!$B$2:$B$1000,"Optional"))>0),"ERROR: pim_contract requirement required for this pim_field","OK"))))),IF(C10="AI_TEXT",IF(E10<>"","ERROR: generation must be blank for AI_TEXT",IF(F10<>"","ERROR: constant_value must be blank for AI_TEXT",IF(D10="","OK",IF(NOT(COUNTIF('pim_contract'!$A$2:$A$1000,D10)>0),"ERROR: pim_field is not on pim_contract",IF(NOT((COUNTIFS('pim_contract'!$A$2:$A$1000,D10,'pim_contract'!$B$2:$B$1000,"Mandatory")+COUNTIFS('pim_contract'!$A$2:$A$1000,D10,'pim_contract'!$B$2:$B$1000,"Optional"))>0),"ERROR: pim_contract requirement required for this pim_field","OK"))))),IF(C10="COPY_GENERATION",IF(E10="","ERROR: COPY_GENERATION requires generation",IF(COUNTIF('lists'!$C$2:$C$9,E10)=0,"ERROR: generation is not in the lists sheet",IF(D10<>"","ERROR: pim_field must be blank for COPY_GENERATION",IF(F10<>"","ERROR: constant_value must be blank for COPY_GENERATION","OK")))),IF(C10="IMAGE",IF(E10="","ERROR: IMAGE requires generation",IF(COUNTIF('lists'!$C$2:$C$9,E10)=0,"ERROR: generation is not in the lists sheet",IF(D10<>"","ERROR: pim_field must be blank for IMAGE",IF(F10<>"","ERROR: constant_value must be blank for IMAGE","OK")))),IF(C10="CONSTANT",IF(F10="","ERROR: CONSTANT requires constant_value",IF(D10<>"","ERROR: pim_field must be blank for CONSTANT",IF(E10<>"","ERROR: generation must be blank for CONSTANT","OK"))),IF(C10="SKIP",IF(D10<>"","ERROR: pim_field must be blank for SKIP",IF(E10<>"","ERROR: generation must be blank for SKIP",IF(F10<>"","ERROR: constant_value must be blank for SKIP","OK"))),"ERROR: unhandled fill_mode")))))))))))))
A11: 10 | B11: Other Image URL | C11: IMAGE | E11: IMAGE | G11: =IF(AND(OR(A11="",A11=0),C11=""),"",IF(OR(A11="",A11=0),"ERROR: column_index required",IF(B11="","ERROR: marketplace_column required",IF(COUNTIF($A$2:$A$320,A11)>1,"ERROR: duplicate column_index",IF(C11="","ERROR: fill_mode required",IF(COUNTIF('lists'!$A$2:$A$8,C11)=0,"ERROR: invalid fill_mode",IF(C11="COPY_PIM",IF(D11="","ERROR: COPY_PIM requires pim_field",IF(NOT(COUNTIF('pim_contract'!$A$2:$A$1000,D11)>0),"ERROR: pim_field is not on pim_contract",IF(NOT((COUNTIFS('pim_contract'!$A$2:$A$1000,D11,'pim_contract'!$B$2:$B$1000,"Mandatory")+COUNTIFS('pim_contract'!$A$2:$A$1000,D11,'pim_contract'!$B$2:$B$1000,"Optional"))>0),"ERROR: pim_contract requirement required for this pim_field",IF(E11<>"","ERROR: generation must be blank for COPY_PIM",IF(F11<>"","ERROR: constant_value must be blank for COPY_PIM","OK"))))),IF(C11="ENUM",IF(E11<>"","ERROR: generation must be blank for ENUM",IF(F11<>"","ERROR: constant_value must be blank for ENUM",IF(D11="","OK",IF(NOT(COUNTIF('pim_contract'!$A$2:$A$1000,D11)>0),"ERROR: pim_field is not on pim_contract",IF(NOT((COUNTIFS('pim_contract'!$A$2:$A$1000,D11,'pim_contract'!$B$2:$B$1000,"Mandatory")+COUNTIFS('pim_contract'!$A$2:$A$1000,D11,'pim_contract'!$B$2:$B$1000,"Optional"))>0),"ERROR: pim_contract requirement required for this pim_field","OK"))))),IF(C11="AI_TEXT",IF(E11<>"","ERROR: generation must be blank for AI_TEXT",IF(F11<>"","ERROR: constant_value must be blank for AI_TEXT",IF(D11="","OK",IF(NOT(COUNTIF('pim_contract'!$A$2:$A$1000,D11)>0),"ERROR: pim_field is not on pim_contract",IF(NOT((COUNTIFS('pim_contract'!$A$2:$A$1000,D11,'pim_contract'!$B$2:$B$1000,"Mandatory")+COUNTIFS('pim_contract'!$A$2:$A$1000,D11,'pim_contract'!$B$2:$B$1000,"Optional"))>0),"ERROR: pim_contract requirement required for this pim_field","OK"))))),IF(C11="COPY_GENERATION",IF(E11="","ERROR: COPY_GENERATION requires generation",IF(COUNTIF('lists'!$C$2:$C$9,E11)=0,"ERROR: generation is not in the lists sheet",IF(D11<>"","ERROR: pim_field must be blank for COPY_GENERATION",IF(F11<>"","ERROR: constant_value must be blank for COPY_GENERATION","OK")))),IF(C11="IMAGE",IF(E11="","ERROR: IMAGE requires generation",IF(COUNTIF('lists'!$C$2:$C$9,E11)=0,"ERROR: generation is not in the lists sheet",IF(D11<>"","ERROR: pim_field must be blank for IMAGE",IF(F11<>"","ERROR: constant_value must be blank for IMAGE","OK")))),IF(C11="CONSTANT",IF(F11="","ERROR: CONSTANT requires constant_value",IF(D11<>"","ERROR: pim_field must be blank for CONSTANT",IF(E11<>"","ERROR: generation must be blank for CONSTANT","OK"))),IF(C11="SKIP",IF(D11<>"","ERROR: pim_field must be blank for SKIP",IF(E11<>"","ERROR: generation must be blank for SKIP",IF(F11<>"","ERROR: constant_value must be blank for SKIP","OK"))),"ERROR: unhandled fill_mode")))))))))))))
A12: 11 | B12: Product Description | C12: COPY_GENERATION | E12: DESCRIPTION | G12: =IF(AND(OR(A12="",A12=0),C12=""),"",IF(OR(A12="",A12=0),"ERROR: column_index required",IF(B12="","ERROR: marketplace_column required",IF(COUNTIF($A$2:$A$320,A12)>1,"ERROR: duplicate column_index",IF(C12="","ERROR: fill_mode required",IF(COUNTIF('lists'!$A$2:$A$8,C12)=0,"ERROR: invalid fill_mode",IF(C12="COPY_PIM",IF(D12="","ERROR: COPY_PIM requires pim_field",IF(NOT(COUNTIF('pim_contract'!$A$2:$A$1000,D12)>0),"ERROR: pim_field is not on pim_contract",IF(NOT((COUNTIFS('pim_contract'!$A$2:$A$1000,D12,'pim_contract'!$B$2:$B$1000,"Mandatory")+COUNTIFS('pim_contract'!$A$2:$A$1000,D12,'pim_contract'!$B$2:$B$1000,"Optional"))>0),"ERROR: pim_contract requirement required for this pim_field",IF(E12<>"","ERROR: generation must be blank for COPY_PIM",IF(F12<>"","ERROR: constant_value must be blank for COPY_PIM","OK"))))),IF(C12="ENUM",IF(E12<>"","ERROR: generation must be blank for ENUM",IF(F12<>"","ERROR: constant_value must be blank for ENUM",IF(D12="","OK",IF(NOT(COUNTIF('pim_contract'!$A$2:$A$1000,D12)>0),"ERROR: pim_field is not on pim_contract",IF(NOT((COUNTIFS('pim_contract'!$A$2:$A$1000,D12,'pim_contract'!$B$2:$B$1000,"Mandatory")+COUNTIFS('pim_contract'!$A$2:$A$1000,D12,'pim_contract'!$B$2:$B$1000,"Optional"))>0),"ERROR: pim_contract requirement required for this pim_field","OK"))))),IF(C12="AI_TEXT",IF(E12<>"","ERROR: generation must be blank for AI_TEXT",IF(F12<>"","ERROR: constant_value must be blank for AI_TEXT",IF(D12="","OK",IF(NOT(COUNTIF('pim_contract'!$A$2:$A$1000,D12)>0),"ERROR: pim_field is not on pim_contract",IF(NOT((COUNTIFS('pim_contract'!$A$2:$A$1000,D12,'pim_contract'!$B$2:$B$1000,"Mandatory")+COUNTIFS('pim_contract'!$A$2:$A$1000,D12,'pim_contract'!$B$2:$B$1000,"Optional"))>0),"ERROR: pim_contract requirement required for this pim_field","OK"))))),IF(C12="COPY_GENERATION",IF(E12="","ERROR: COPY_GENERATION requires generation",IF(COUNTIF('lists'!$C$2:$C$9,E12)=0,"ERROR: generation is not in the lists sheet",IF(D12<>"","ERROR: pim_field must be blank for COPY_GENERATION",IF(F12<>"","ERROR: constant_value must be blank for COPY_GENERATION","OK")))),IF(C12="IMAGE",IF(E12="","ERROR: IMAGE requires generation",IF(COUNTIF('lists'!$C$2:$C$9,E12)=0,"ERROR: generation is not in the lists sheet",IF(D12<>"","ERROR: pim_field must be blank for IMAGE",IF(F12<>"","ERROR: constant_value must be blank for IMAGE","OK")))),IF(C12="CONSTANT",IF(F12="","ERROR: CONSTANT requires constant_value",IF(D12<>"","ERROR: pim_field must be blank for CONSTANT",IF(E12<>"","ERROR: generation must be blank for CONSTANT","OK"))),IF(C12="SKIP",IF(D12<>"","ERROR: pim_field must be blank for SKIP",IF(E12<>"","ERROR: generation must be blank for SKIP",IF(F12<>"","ERROR: constant_value must be blank for SKIP","OK"))),"ERROR: unhandled fill_mode")))))))))))))
A13: 12 | B13: Bullet Point | C13: COPY_GENERATION | E13: BULLET_POINTS | G13: =IF(AND(OR(A13="",A13=0),C13=""),"",IF(OR(A13="",A13=0),"ERROR: column_index required",IF(B13="","ERROR: marketplace_column required",IF(COUNTIF($A$2:$A$320,A13)>1,"ERROR: duplicate column_index",IF(C13="","ERROR: fill_mode required",IF(COUNTIF('lists'!$A$2:$A$8,C13)=0,"ERROR: invalid fill_mode",IF(C13="COPY_PIM",IF(D13="","ERROR: COPY_PIM requires pim_field",IF(NOT(COUNTIF('pim_contract'!$A$2:$A$1000,D13)>0),"ERROR: pim_field is not on pim_contract",IF(NOT((COUNTIFS('pim_contract'!$A$2:$A$1000,D13,'pim_contract'!$B$2:$B$1000,"Mandatory")+COUNTIFS('pim_contract'!$A$2:$A$1000,D13,'pim_contract'!$B$2:$B$1000,"Optional"))>0),"ERROR: pim_contract requirement required for this pim_field",IF(E13<>"","ERROR: generation must be blank for COPY_PIM",IF(F13<>"","ERROR: constant_value must be blank for COPY_PIM","OK"))))),IF(C13="ENUM",IF(E13<>"","ERROR: generation must be blank for ENUM",IF(F13<>"","ERROR: constant_value must be blank for ENUM",IF(D13="","OK",IF(NOT(COUNTIF('pim_contract'!$A$2:$A$1000,D13)>0),"ERROR: pim_field is not on pim_contract",IF(NOT((COUNTIFS('pim_contract'!$A$2:$A$1000,D13,'pim_contract'!$B$2:$B$1000,"Mandatory")+COUNTIFS('pim_contract'!$A$2:$A$1000,D13,'pim_contract'!$B$2:$B$1000,"Optional"))>0),"ERROR: pim_contract requirement required for this pim_field","OK"))))),IF(C13="AI_TEXT",IF(E13<>"","ERROR: generation must be blank for AI_TEXT",IF(F13<>"","ERROR: constant_value must be blank for AI_TEXT",IF(D13="","OK",IF(NOT(COUNTIF('pim_contract'!$A$2:$A$1000,D13)>0),"ERROR: pim_field is not on pim_contract",IF(NOT((COUNTIFS('pim_contract'!$A$2:$A$1000,D13,'pim_contract'!$B$2:$B$1000,"Mandatory")+COUNTIFS('pim_contract'!$A$2:$A$1000,D13,'pim_contract'!$B$2:$B$1000,"Optional"))>0),"ERROR: pim_contract requirement required for this pim_field","OK"))))),IF(C13="COPY_GENERATION",IF(E13="","ERROR: COPY_GENERATION requires generation",IF(COUNTIF('lists'!$C$2:$C$9,E13)=0,"ERROR: generation is not in the lists sheet",IF(D13<>"","ERROR: pim_field must be blank for COPY_GENERATION",IF(F13<>"","ERROR: constant_value must be blank for COPY_GENERATION","OK")))),IF(C13="IMAGE",IF(E13="","ERROR: IMAGE requires generation",IF(COUNTIF('lists'!$C$2:$C$9,E13)=0,"ERROR: generation is not in the lists sheet",IF(D13<>"","ERROR: pim_field must be blank for IMAGE",IF(F13<>"","ERROR: constant_value must be blank for IMAGE","OK")))),IF(C13="CONSTANT",IF(F13="","ERROR: CONSTANT requires constant_value",IF(D13<>"","ERROR: pim_field must be blank for CONSTANT",IF(E13<>"","ERROR: generation must be blank for CONSTANT","OK"))),IF(C13="SKIP",IF(D13<>"","ERROR: pim_field must be blank for SKIP",IF(E13<>"","ERROR: generation must be blank for SKIP",IF(F13<>"","ERROR: constant_value must be blank for SKIP","OK"))),"ERROR: unhandled fill_mode")))))))))))))
A14: 13 | B14: Bullet Point | C14: COPY_GENERATION | E14: BULLET_POINTS | G14: =IF(AND(OR(A14="",A14=0),C14=""),"",IF(OR(A14="",A14=0),"ERROR: column_index required",IF(B14="","ERROR: marketplace_column required",IF(COUNTIF($A$2:$A$320,A14)>1,"ERROR: duplicate column_index",IF(C14="","ERROR: fill_mode required",IF(COUNTIF('lists'!$A$2:$A$8,C14)=0,"ERROR: invalid fill_mode",IF(C14="COPY_PIM",IF(D14="","ERROR: COPY_PIM requires pim_field",IF(NOT(COUNTIF('pim_contract'!$A$2:$A$1000,D14)>0),"ERROR: pim_field is not on pim_contract",IF(NOT((COUNTIFS('pim_contract'!$A$2:$A$1000,D14,'pim_contract'!$B$2:$B$1000,"Mandatory")+COUNTIFS('pim_contract'!$A$2:$A$1000,D14,'pim_contract'!$B$2:$B$1000,"Optional"))>0),"ERROR: pim_contract requirement required for this pim_field",IF(E14<>"","ERROR: generation must be blank for COPY_PIM",IF(F14<>"","ERROR: constant_value must be blank for COPY_PIM","OK"))))),IF(C14="ENUM",IF(E14<>"","ERROR: generation must be blank for ENUM",IF(F14<>"","ERROR: constant_value must be blank for ENUM",IF(D14="","OK",IF(NOT(COUNTIF('pim_contract'!$A$2:$A$1000,D14)>0),"ERROR: pim_field is not on pim_contract",IF(NOT((COUNTIFS('pim_contract'!$A$2:$A$1000,D14,'pim_contract'!$B$2:$B$1000,"Mandatory")+COUNTIFS('pim_contract'!$A$2:$A$1000,D14,'pim_contract'!$B$2:$B$1000,"Optional"))>0),"ERROR: pim_contract requirement required for this pim_field","OK"))))),IF(C14="AI_TEXT",IF(E14<>"","ERROR: generation must be blank for AI_TEXT",IF(F14<>"","ERROR: constant_value must be blank for AI_TEXT",IF(D14="","OK",IF(NOT(COUNTIF('pim_contract'!$A$2:$A$1000,D14)>0),"ERROR: pim_field is not on pim_contract",IF(NOT((COUNTIFS('pim_contract'!$A$2:$A$1000,D14,'pim_contract'!$B$2:$B$1000,"Mandatory")+COUNTIFS('pim_contract'!$A$2:$A$1000,D14,'pim_contract'!$B$2:$B$1000,"Optional"))>0),"ERROR: pim_contract requirement required for this pim_field","OK"))))),IF(C14="COPY_GENERATION",IF(E14="","ERROR: COPY_GENERATION requires generation",IF(COUNTIF('lists'!$C$2:$C$9,E14)=0,"ERROR: generation is not in the lists sheet",IF(D14<>"","ERROR: pim_field must be blank for COPY_GENERATION",IF(F14<>"","ERROR: constant_value must be blank for COPY_GENERATION","OK")))),IF(C14="IMAGE",IF(E14="","ERROR: IMAGE requires generation",IF(COUNTIF('lists'!$C$2:$C$9,E14)=0,"ERROR: generation is not in the lists sheet",IF(D14<>"","ERROR: pim_field must be blank for IMAGE",IF(F14<>"","ERROR: constant_value must be blank for IMAGE","OK")))),IF(C14="CONSTANT",IF(F14="","ERROR: CONSTANT requires constant_value",IF(D14<>"","ERROR: pim_field must be blank for CONSTANT",IF(E14<>"","ERROR: generation must be blank for CONSTANT","OK"))),IF(C14="SKIP",IF(D14<>"","ERROR: pim_field must be blank for SKIP",IF(E14<>"","ERROR: generation must be blank for SKIP",IF(F14<>"","ERROR: constant_value must be blank for SKIP","OK"))),"ERROR: unhandled fill_mode")))))))))))))
A15: 14 | B15: Generic Keyword | C15: COPY_GENERATION | E15: BACKEND_KEYWORDS | G15: =IF(AND(OR(A15="",A15=0),C15=""),"",IF(OR(A15="",A15=0),"ERROR: column_index required",IF(B15="","ERROR: marketplace_column required",IF(COUNTIF($A$2:$A$320,A15)>1,"ERROR: duplicate column_index",IF(C15="","ERROR: fill_mode required",IF(COUNTIF('lists'!$A$2:$A$8,C15)=0,"ERROR: invalid fill_mode",IF(C15="COPY_PIM",IF(D15="","ERROR: COPY_PIM requires pim_field",IF(NOT(COUNTIF('pim_contract'!$A$2:$A$1000,D15)>0),"ERROR: pim_field is not on pim_contract",IF(NOT((COUNTIFS('pim_contract'!$A$2:$A$1000,D15,'pim_contract'!$B$2:$B$1000,"Mandatory")+COUNTIFS('pim_contract'!$A$2:$A$1000,D15,'pim_contract'!$B$2:$B$1000,"Optional"))>0),"ERROR: pim_contract requirement required for this pim_field",IF(E15<>"","ERROR: generation must be blank for COPY_PIM",IF(F15<>"","ERROR: constant_value must be blank for COPY_PIM","OK"))))),IF(C15="ENUM",IF(E15<>"","ERROR: generation must be blank for ENUM",IF(F15<>"","ERROR: constant_value must be blank for ENUM",IF(D15="","OK",IF(NOT(COUNTIF('pim_contract'!$A$2:$A$1000,D15)>0),"ERROR: pim_field is not on pim_contract",IF(NOT((COUNTIFS('pim_contract'!$A$2:$A$1000,D15,'pim_contract'!$B$2:$B$1000,"Mandatory")+COUNTIFS('pim_contract'!$A$2:$A$1000,D15,'pim_contract'!$B$2:$B$1000,"Optional"))>0),"ERROR: pim_contract requirement required for this pim_field","OK"))))),IF(C15="AI_TEXT",IF(E15<>"","ERROR: generation must be blank for AI_TEXT",IF(F15<>"","ERROR: constant_value must be blank for AI_TEXT",IF(D15="","OK",IF(NOT(COUNTIF('pim_contract'!$A$2:$A$1000,D15)>0),"ERROR: pim_field is not on pim_contract",IF(NOT((COUNTIFS('pim_contract'!$A$2:$A$1000,D15,'pim_contract'!$B$2:$B$1000,"Mandatory")+COUNTIFS('pim_contract'!$A$2:$A$1000,D15,'pim_contract'!$B$2:$B$1000,"Optional"))>0),"ERROR: pim_contract requirement required for this pim_field","OK"))))),IF(C15="COPY_GENERATION",IF(E15="","ERROR: COPY_GENERATION requires generation",IF(COUNTIF('lists'!$C$2:$C$9,E15)=0,"ERROR: generation is not in the lists sheet",IF(D15<>"","ERROR: pim_field must be blank for COPY_GENERATION",IF(F15<>"","ERROR: constant_value must be blank for COPY_GENERATION","OK")))),IF(C15="IMAGE",IF(E15="","ERROR: IMAGE requires generation",IF(COUNTIF('lists'!$C$2:$C$9,E15)=0,"ERROR: generation is not in the lists sheet",IF(D15<>"","ERROR: pim_field must be blank for IMAGE",IF(F15<>"","ERROR: constant_value must be blank for IMAGE","OK")))),IF(C15="CONSTANT",IF(F15="","ERROR: CONSTANT requires constant_value",IF(D15<>"","ERROR: pim_field must be blank for CONSTANT",IF(E15<>"","ERROR: generation must be blank for CONSTANT","OK"))),IF(C15="SKIP",IF(D15<>"","ERROR: pim_field must be blank for SKIP",IF(E15<>"","ERROR: generation must be blank for SKIP",IF(F15<>"","ERROR: constant_value must be blank for SKIP","OK"))),"ERROR: unhandled fill_mode")))))))))))))
A16: 15 | B16: Item Type Name | C16: AI_TEXT | G16: =IF(AND(OR(A16="",A16=0),C16=""),"",IF(OR(A16="",A16=0),"ERROR: column_index required",IF(B16="","ERROR: marketplace_column required",IF(COUNTIF($A$2:$A$320,A16)>1,"ERROR: duplicate column_index",IF(C16="","ERROR: fill_mode required",IF(COUNTIF('lists'!$A$2:$A$8,C16)=0,"ERROR: invalid fill_mode",IF(C16="COPY_PIM",IF(D16="","ERROR: COPY_PIM requires pim_field",IF(NOT(COUNTIF('pim_contract'!$A$2:$A$1000,D16)>0),"ERROR: pim_field is not on pim_contract",IF(NOT((COUNTIFS('pim_contract'!$A$2:$A$1000,D16,'pim_contract'!$B$2:$B$1000,"Mandatory")+COUNTIFS('pim_contract'!$A$2:$A$1000,D16,'pim_contract'!$B$2:$B$1000,"Optional"))>0),"ERROR: pim_contract requirement required for this pim_field",IF(E16<>"","ERROR: generation must be blank for COPY_PIM",IF(F16<>"","ERROR: constant_value must be blank for COPY_PIM","OK"))))),IF(C16="ENUM",IF(E16<>"","ERROR: generation must be blank for ENUM",IF(F16<>"","ERROR: constant_value must be blank for ENUM",IF(D16="","OK",IF(NOT(COUNTIF('pim_contract'!$A$2:$A$1000,D16)>0),"ERROR: pim_field is not on pim_contract",IF(NOT((COUNTIFS('pim_contract'!$A$2:$A$1000,D16,'pim_contract'!$B$2:$B$1000,"Mandatory")+COUNTIFS('pim_contract'!$A$2:$A$1000,D16,'pim_contract'!$B$2:$B$1000,"Optional"))>0),"ERROR: pim_contract requirement required for this pim_field","OK"))))),IF(C16="AI_TEXT",IF(E16<>"","ERROR: generation must be blank for AI_TEXT",IF(F16<>"","ERROR: constant_value must be blank for AI_TEXT",IF(D16="","OK",IF(NOT(COUNTIF('pim_contract'!$A$2:$A$1000,D16)>0),"ERROR: pim_field is not on pim_contract",IF(NOT((COUNTIFS('pim_contract'!$A$2:$A$1000,D16,'pim_contract'!$B$2:$B$1000,"Mandatory")+COUNTIFS('pim_contract'!$A$2:$A$1000,D16,'pim_contract'!$B$2:$B$1000,"Optional"))>0),"ERROR: pim_contract requirement required for this pim_field","OK"))))),IF(C16="COPY_GENERATION",IF(E16="","ERROR: COPY_GENERATION requires generation",IF(COUNTIF('lists'!$C$2:$C$9,E16)=0,"ERROR: generation is not in the lists sheet",IF(D16<>"","ERROR: pim_field must be blank for COPY_GENERATION",IF(F16<>"","ERROR: constant_value must be blank for COPY_GENERATION","OK")))),IF(C16="IMAGE",IF(E16="","ERROR: IMAGE requires generation",IF(COUNTIF('lists'!$C$2:$C$9,E16)=0,"ERROR: generation is not in the lists sheet",IF(D16<>"","ERROR: pim_field must be blank for IMAGE",IF(F16<>"","ERROR: constant_value must be blank for IMAGE","OK")))),IF(C16="CONSTANT",IF(F16="","ERROR: CONSTANT requires constant_value",IF(D16<>"","ERROR: pim_field must be blank for CONSTANT",IF(E16<>"","ERROR: generation must be blank for CONSTANT","OK"))),IF(C16="SKIP",IF(D16<>"","ERROR: pim_field must be blank for SKIP",IF(E16<>"","ERROR: generation must be blank for SKIP",IF(F16<>"","ERROR: constant_value must be blank for SKIP","OK"))),"ERROR: unhandled fill_mode")))))))))))))
A17: 16 | B17: Fabric Type | C17: AI_TEXT | D17: Color | G17: =IF(AND(OR(A17="",A17=0),C17=""),"",IF(OR(A17="",A17=0),"ERROR: column_index required",IF(B17="","ERROR: marketplace_column required",IF(COUNTIF($A$2:$A$320,A17)>1,"ERROR: duplicate column_index",IF(C17="","ERROR: fill_mode required",IF(COUNTIF('lists'!$A$2:$A$8,C17)=0,"ERROR: invalid fill_mode",IF(C17="COPY_PIM",IF(D17="","ERROR: COPY_PIM requires pim_field",IF(NOT(COUNTIF('pim_contract'!$A$2:$A$1000,D17)>0),"ERROR: pim_field is not on pim_contract",IF(NOT((COUNTIFS('pim_contract'!$A$2:$A$1000,D17,'pim_contract'!$B$2:$B$1000,"Mandatory")+COUNTIFS('pim_contract'!$A$2:$A$1000,D17,'pim_contract'!$B$2:$B$1000,"Optional"))>0),"ERROR: pim_contract requirement required for this pim_field",IF(E17<>"","ERROR: generation must be blank for COPY_PIM",IF(F17<>"","ERROR: constant_value must be blank for COPY_PIM","OK"))))),IF(C17="ENUM",IF(E17<>"","ERROR: generation must be blank for ENUM",IF(F17<>"","ERROR: constant_value must be blank for ENUM",IF(D17="","OK",IF(NOT(COUNTIF('pim_contract'!$A$2:$A$1000,D17)>0),"ERROR: pim_field is not on pim_contract",IF(NOT((COUNTIFS('pim_contract'!$A$2:$A$1000,D17,'pim_contract'!$B$2:$B$1000,"Mandatory")+COUNTIFS('pim_contract'!$A$2:$A$1000,D17,'pim_contract'!$B$2:$B$1000,"Optional"))>0),"ERROR: pim_contract requirement required for this pim_field","OK"))))),IF(C17="AI_TEXT",IF(E17<>"","ERROR: generation must be blank for AI_TEXT",IF(F17<>"","ERROR: constant_value must be blank for AI_TEXT",IF(D17="","OK",IF(NOT(COUNTIF('pim_contract'!$A$2:$A$1000,D17)>0),"ERROR: pim_field is not on pim_contract",IF(NOT((COUNTIFS('pim_contract'!$A$2:$A$1000,D17,'pim_contract'!$B$2:$B$1000,"Mandatory")+COUNTIFS('pim_contract'!$A$2:$A$1000,D17,'pim_contract'!$B$2:$B$1000,"Optional"))>0),"ERROR: pim_contract requirement required for this pim_field","OK"))))),IF(C17="COPY_GENERATION",IF(E17="","ERROR: COPY_GENERATION requires generation",IF(COUNTIF('lists'!$C$2:$C$9,E17)=0,"ERROR: generation is not in the lists sheet",IF(D17<>"","ERROR: pim_field must be blank for COPY_GENERATION",IF(F17<>"","ERROR: constant_value must be blank for COPY_GENERATION","OK")))),IF(C17="IMAGE",IF(E17="","ERROR: IMAGE requires generation",IF(COUNTIF('lists'!$C$2:$C$9,E17)=0,"ERROR: generation is not in the lists sheet",IF(D17<>"","ERROR: pim_field must be blank for IMAGE",IF(F17<>"","ERROR: constant_value must be blank for IMAGE","OK")))),IF(C17="CONSTANT",IF(F17="","ERROR: CONSTANT requires constant_value",IF(D17<>"","ERROR: pim_field must be blank for CONSTANT",IF(E17<>"","ERROR: generation must be blank for CONSTANT","OK"))),IF(C17="SKIP",IF(D17<>"","ERROR: pim_field must be blank for SKIP",IF(E17<>"","ERROR: generation must be blank for SKIP",IF(F17<>"","ERROR: constant_value must be blank for SKIP","OK"))),"ERROR: unhandled fill_mode")))))))))))))
G18: =IF(AND(OR(A18="",A18=0),C18=""),"",IF(OR(A18="",A18=0),"ERROR: column_index required",IF(B18="","ERROR: marketplace_column required",IF(COUNTIF($A$2:$A$320,A18)>1,"ERROR: duplicate column_index",IF(C18="","ERROR: fill_mode required",IF(COUNTIF('lists'!$A$2:$A$8,C18)=0,"ERROR: invalid fill_mode",IF(C18="COPY_PIM",IF(D18="","ERROR: COPY_PIM requires pim_field",IF(NOT(COUNTIF('pim_contract'!$A$2:$A$1000,D18)>0),"ERROR: pim_field is not on pim_contract",IF(NOT((COUNTIFS('pim_contract'!$A$2:$A$1000,D18,'pim_contract'!$B$2:$B$1000,"Mandatory")+COUNTIFS('pim_contract'!$A$2:$A$1000,D18,'pim_contract'!$B$2:$B$1000,"Optional"))>0),"ERROR: pim_contract requirement required for this pim_field",IF(E18<>"","ERROR: generation must be blank for COPY_PIM",IF(F18<>"","ERROR: constant_value must be blank for COPY_PIM","OK"))))),IF(C18="ENUM",IF(E18<>"","ERROR: generation must be blank for ENUM",IF(F18<>"","ERROR: constant_value must be blank for ENUM",IF(D18="","OK",IF(NOT(COUNTIF('pim_contract'!$A$2:$A$1000,D18)>0),"ERROR: pim_field is not on pim_contract",IF(NOT((COUNTIFS('pim_contract'!$A$2:$A$1000,D18,'pim_contract'!$B$2:$B$1000,"Mandatory")+COUNTIFS('pim_contract'!$A$2:$A$1000,D18,'pim_contract'!$B$2:$B$1000,"Optional"))>0),"ERROR: pim_contract requirement required for this pim_field","OK"))))),IF(C18="AI_TEXT",IF(E18<>"","ERROR: generation must be blank for AI_TEXT",IF(F18<>"","ERROR: constant_value must be blank for AI_TEXT",IF(D18="","OK",IF(NOT(COUNTIF('pim_contract'!$A$2:$A$1000,D18)>0),"ERROR: pim_field is not on pim_contract",IF(NOT((COUNTIFS('pim_contract'!$A$2:$A$1000,D18,'pim_contract'!$B$2:$B$1000,"Mandatory")+COUNTIFS('pim_contract'!$A$2:$A$1000,D18,'pim_contract'!$B$2:$B$1000,"Optional"))>0),"ERROR: pim_contract requirement required for this pim_field","OK"))))),IF(C18="COPY_GENERATION",IF(E18="","ERROR: COPY_GENERATION requires generation",IF(COUNTIF('lists'!$C$2:$C$9,E18)=0,"ERROR: generation is not in the lists sheet",IF(D18<>"","ERROR: pim_field must be blank for COPY_GENERATION",IF(F18<>"","ERROR: constant_value must be blank for COPY_GENERATION","OK")))),IF(C18="IMAGE",IF(E18="","ERROR: IMAGE requires generation",IF(COUNTIF('lists'!$C$2:$C$9,E18)=0,"ERROR: generation is not in the lists sheet",IF(D18<>"","ERROR: pim_field must be blank for IMAGE",IF(F18<>"","ERROR: constant_value must be blank for IMAGE","OK")))),IF(C18="CONSTANT",IF(F18="","ERROR: CONSTANT requires constant_value",IF(D18<>"","ERROR: pim_field must be blank for CONSTANT",IF(E18<>"","ERROR: generation must be blank for CONSTANT","OK"))),IF(C18="SKIP",IF(D18<>"","ERROR: pim_field must be blank for SKIP",IF(E18<>"","ERROR: generation must be blank for SKIP",IF(F18<>"","ERROR: constant_value must be blank for SKIP","OK"))),"ERROR: unhandled fill_mode")))))))))))))
G19: =IF(AND(OR(A19="",A19=0),C19=""),"",IF(OR(A19="",A19=0),"ERROR: column_index required",IF(B19="","ERROR: marketplace_column required",IF(COUNTIF($A$2:$A$320,A19)>1,"ERROR: duplicate column_index",IF(C19="","ERROR: fill_mode required",IF(COUNTIF('lists'!$A$2:$A$8,C19)=0,"ERROR: invalid fill_mode",IF(C19="COPY_PIM",IF(D19="","ERROR: COPY_PIM requires pim_field",IF(NOT(COUNTIF('pim_contract'!$A$2:$A$1000,D19)>0),"ERROR: pim_field is not on pim_contract",IF(NOT((COUNTIFS('pim_contract'!$A$2:$A$1000,D19,'pim_contract'!$B$2:$B$1000,"Mandatory")+COUNTIFS('pim_contract'!$A$2:$A$1000,D19,'pim_contract'!$B$2:$B$1000,"Optional"))>0),"ERROR: pim_contract requirement required for this pim_field",IF(E19<>"","ERROR: generation must be blank for COPY_PIM",IF(F19<>"","ERROR: constant_value must be blank for COPY_PIM","OK"))))),IF(C19="ENUM",IF(E19<>"","ERROR: generation must be blank for ENUM",IF(F19<>"","ERROR: constant_value must be blank for ENUM",IF(D19="","OK",IF(NOT(COUNTIF('pim_contract'!$A$2:$A$1000,D19)>0),"ERROR: pim_field is not on pim_contract",IF(NOT((COUNTIFS('pim_contract'!$A$2:$A$1000,D19,'pim_contract'!$B$2:$B$1000,"Mandatory")+COUNTIFS('pim_contract'!$A$2:$A$1000,D19,'pim_contract'!$B$2:$B$1000,"Optional"))>0),"ERROR: pim_contract requirement required for this pim_field","OK"))))),IF(C19="AI_TEXT",IF(E19<>"","ERROR: generation must be blank for AI_TEXT",IF(F19<>"","ERROR: constant_value must be blank for AI_TEXT",IF(D19="","OK",IF(NOT(COUNTIF('pim_contract'!$A$2:$A$1000,D19)>0),"ERROR: pim_field is not on pim_contract",IF(NOT((COUNTIFS('pim_contract'!$A$2:$A$1000,D19,'pim_contract'!$B$2:$B$1000,"Mandatory")+COUNTIFS('pim_contract'!$A$2:$A$1000,D19,'pim_contract'!$B$2:$B$1000,"Optional"))>0),"ERROR: pim_contract requirement required for this pim_field","OK"))))),IF(C19="COPY_GENERATION",IF(E19="","ERROR: COPY_GENERATION requires generation",IF(COUNTIF('lists'!$C$2:$C$9,E19)=0,"ERROR: generation is not in the lists sheet",IF(D19<>"","ERROR: pim_field must be blank for COPY_GENERATION",IF(F19<>"","ERROR: constant_value must be blank for COPY_GENERATION","OK")))),IF(C19="IMAGE",IF(E19="","ERROR: IMAGE requires generation",IF(COUNTIF('lists'!$C$2:$C$9,E19)=0,"ERROR: generation is not in the lists sheet",IF(D19<>"","ERROR: pim_field must be blank for IMAGE",IF(F19<>"","ERROR: constant_value must be blank for IMAGE","OK")))),IF(C19="CONSTANT",IF(F19="","ERROR: CONSTANT requires constant_value",IF(D19<>"","ERROR: pim_field must be blank for CONSTANT",IF(E19<>"","ERROR: generation must be blank for CONSTANT","OK"))),IF(C19="SKIP",IF(D19<>"","ERROR: pim_field must be blank for SKIP",IF(E19<>"","ERROR: generation must be blank for SKIP",IF(F19<>"","ERROR: constant_value must be blank for SKIP","OK"))),"ERROR: unhandled fill_mode")))))))))))))
